Workbook
Name LST_Classes: Référentiels!$B$5:$B$27
Name LST_Matieres: Référentiels!$G$5:$G$24
Name LST_Profs: Référentiels!$K$5:$K$41
Name LST_Salles: Référentiels!$O$5:$O$16
Name LST_Modes: Référentiels!$Q$5:$Q$7
Name LST_Rythmes: Référentiels!$S$5:$S$9
Name LST_Statuts: Référentiels!$AB$5:$AB$10

Sheet Sommaire
B2: EMPLOI DU TEMPS — ANNÉE SCOLAIRE 2026-2027
B3: Septembre et octobre 2026 · 23 classes · 7 semaines · du 14 septembre au 1er novembre 2026
B5: NAVIGATION — cliquer sur un nom de feuille
B6: Feuille | C6: Contenu | D6: Séances | E6: Type
B7: Planning | C7: Table de référence : 1 ligne = 1 groupe dans une séance. C’est ICI que l’on modifie les données. | D7: =COUNTIF(Planning!$S$4:$S$863,"Oui") | E7: Saisie
B8: Référentiels | C8: Listes des classes, matières, enseignants, salles, modes, rythmes et semaines. | D8: — | E8: Paramètres
B9: Contrôles | C9: 21 contrôles automatiques + toutes les décisions prises pour construire octobre. | D9: — | E9: Fiabilité
B10: Récapitulatif | C10: Indicateurs : volumes par semaine, cycle, matière et jour. | D10: — | E10: Pilotage
B11: Vue Enseignants | C11: Charge de chaque enseignant, semaine par semaine (séances et heures). | D11: — | E11: Pilotage
B12: S1 14-20 sept | C12: Grille imprimable — du 14 au 20 septembre 2026 (semaine A). | D12: =COUNTIFS(Planning!$A$4:$A$863,"S1",Planning!$S$4:$S$863,"Oui") | E12: Septembre
B13: S2 21-27 sept | C13: Grille imprimable — du 21 au 27 septembre 2026 (semaine B). | D13: =COUNTIFS(Planning!$A$4:$A$863,"S2",Planning!$S$4:$S$863,"Oui") | E13: Septembre
B14: S3 28 sept-04 oct | C14: Grille imprimable — du 28 septembre au 4 octobre 2026 (semaine A). | D14: =COUNTIFS(Planning!$A$4:$A$863,"S3",Planning!$S$4:$S$863,"Oui") | E14: Référence
B15: S4 05-11 oct | C15: Grille imprimable — du 5 au 11 octobre 2026 (semaine B). | D15: =COUNTIFS(Planning!$A$4:$A$863,"S4",Planning!$S$4:$S$863,"Oui") | E15: Octobre
B16: S5 12-18 oct | C16: Grille imprimable — du 12 au 18 octobre 2026 (semaine A). | D16: =COUNTIFS(Planning!$A$4:$A$863,"S5",Planning!$S$4:$S$863,"Oui") | E16: Octobre
B17: S6 19-25 oct | C17: Grille imprimable — du 19 au 25 octobre 2026 (semaine B). | D17: =COUNTIFS(Planning!$A$4:$A$863,"S6",Planning!$S$4:$S$863,"Oui") | E17: Octobre
B18: S7 26 oct-01 nov | C18: Grille imprimable — du 26 octobre au 1er novembre 2026 (semaine A). | D18: =COUNTIFS(Planning!$A$4:$A$863,"S7",Planning!$S$4:$S$863,"Oui") | E18: Octobre
B20: LÉGENDE
B21: COULEUR DES CASES — une couleur par matière
B22: Math | C22: Écrit dans la case : Math ou رياضيات
B23: Physique | C23: Écrit dans la case : Physique ou فيزياء
B24: Français
B25: Arabe | C25: Écrit dans la case : Arabe ou عربية
B26: Anglais
B27: SVT
B28: Éveil scientifique | C28: Écrit dans la case : Éveil scientifique ou إيقاظ علمي
B29: Histoire
B30: Géographie
B31: Philo
B32: Eco
B33: Gestion
B34: Informatique
B35: ALGO
B36: STI
B37: Espagnol
B38: Italien
B39: COULEUR DE LA COLONNE CLASSE — cycle
B40: Primaire | C40: 4éme, 5éme, 6éme Pilote (A), 6éme (B)
B41: Collège | C41: 7éme, 8éme et 9éme (8 groupes)
B42: Secondaire | C42: 1ére, 2éme et 3éme (8 groupes)
B43: Bac | C43: Bac Eco, Bac SCE, Bac INFO
...

Sheet Planning
A1: PLANNING DES SÉANCES — Année scolaire 2026-2027
A2: TABLE DE RÉFÉRENCE : toute modification se fait ici. 1 ligne = 1 groupe dans une séance. Une séance partagée entre plusieurs groupes occupe autant de lignes que de groupes, reliées par le même ID séance (seule la 1re porte « Ligne principale = Oui », pour ne compter l'heure d'enseignement qu'une fois). Colonnes Y à AG = zone technique, ne pas saisir.
A3: Semaine | B3: Période | C3: Parité | D3: Date | E3: Jour | F3: Début | G3: Fin | H3: Durée (h) | I3: Cycle | J3: Classe / Groupe | K3: Matière | L3: Matière (normalisée) | M3: Enseignant | N3: Salle | O3: Mode | P3: Rythme | Q3: Séance partagée avec | R3: Nb groupes | S3: Ligne principale | T3: ID séance | U3: Origine | V3: Notes | W3: Statut | X3: Cours en option | Y3: ⚠ Conflit enseignant | Z3: ⚠ Conflit classe | AA3: ⚠ Doublon | AB3: ⚠ Partage incohérent | AC3: Rang | AD3: Clé | AE3: Libellé grille | AF3: Texte d'origine | AG3: Réf. cellule source
A4: S1 | B4: du 14 au 20 septembre 2026 | C4: A | D4: 46279 | E4: Lundi | F4: 0.79166667 | G4: 0.875 | H4: =IF(OR($F4="",$G4=""),"",($G4-$F4)*24) | I4: Primaire | J4: 4éme | K4: عربية | L4: Arabe | M4: Lobna | P4: Hebdomadaire | R4: 1 | S4: Oui | T4: S1-001 | U4: Original (septembre) | Y4: =IF($M4="","",IF(SUMPRODUCT(($D$4:$D$863=$D4)*($M$4:$M$863=$M4)*($T$4:$T$863<>$T4)*($F$4:$F$863<$G4)*($G$4:$G$863>$F4))>0,"⚠ CONFLIT","")) | Z4: =IF($J4="","",IF(SUMPRODUCT(($D$4:$D$863=$D4)*($J$4:$J$863=$J4)*($T$4:$T$863<>$T4)*($F$4:$F$863<$G4)*($G$4:$G$863>$F4)*(1-($X$4:$X$863="Oui")*($X4="Oui")))>0,"⚠ CONFLIT","")) | AA4: =IF(COUNTIFS($D$4:$D$863,$D4,$J$4:$J$863,$J4,$F$4:$F$863,$F4,$K$4:$K$863,$K4)>1,"⚠ DOUBLON","") | AB4: =IF(COUNTIF($T$4:$T$863,$T4)<>COUNTIFS($T$4:$T$863,$T4,$D$4:$D$863,$D4,$F$4:$F$863,$F4,$G$4:$G$863,$G4,$K$4:$K$863,$K4,$M$4:$M$863,$M4),"⚠ INCOHÉRENT","") | AC4: =COUNTIFS($A$4:$A4,$A4,$J$4:$J4,$J4,$E$4:$E4,$E4) | AD4: =$A4&"|"&$J4&"|"&$E4&"|"&$AC4 | AE4: =IF($W4<>"","⚑ "&$W4&CHAR(10),"")&TEXT($F4,"hh:mm")&"-"&TEXT($G4,"hh:mm")&IF(OR($P4="Quinzaine A",AND($P4="Hebdo · groupes alternés",$C4="A"))," Q-A",IF(OR($P4="Quinzaine B",AND($P4="Hebdo · groupes alternés",$C4="B"))," Q-B",IF($P4="Exception"," PONCT.","")))&IF($X4="Oui"," OPT","")&CHAR(10)&$K4&CHAR(10)&$M4&IF($N4<>"",CHAR(10)&"Salle "&$N4,"")&IF($O4="En ligne",CHAR(10)&"EN LIGNE","")&IF($V4<>"",CHAR(10)&$V4,"") | AF4: 19h-21h عربية (Lobna) | AG4: du 14-09 jusquà le 20-09!G3
A5: S1 | B5: du 14 au 20 septembre 2026 | C5: A | D5: 46279 | E5: Lundi | F5: 0.79166667 | G5: 0.85416667 | H5: =IF(OR($F5="",$G5=""),"",($G5-$F5)*24) | I5: Primaire | J5: 6éme Pilote (A) | K5: Français | L5: Français | M5: Hend | P5: Hebdomadaire | R5: 1 | S5: Oui | T5: S1-002 | U5: Original (septembre) | Y5: =IF($M5="","",IF(SUMPRODUCT(($D$4:$D$863=$D5)*($M$4:$M$863=$M5)*($T$4:$T$863<>$T5)*($F$4:$F$863<$G5)*($G$4:$G$863>$F5))>0,"⚠ CONFLIT","")) | Z5: =IF($J5="","",IF(SUMPRODUCT(($D$4:$D$863=$D5)*($J$4:$J$863=$J5)*($T$4:$T$863<>$T5)*($F$4:$F$863<$G5)*($G$4:$G$863>$F5)*(1-($X$4:$X$863="Oui")*($X5="Oui")))>0,"⚠ CONFLIT","")) | AA5: =IF(COUNTIFS($D$4:$D$863,$D5,$J$4:$J$863,$J5,$F$4:$F$863,$F5,$K$4:$K$863,$K5)>1,"⚠ DOUBLON","") | AB5: =IF(COUNTIF($T$4:$T$863,$T5)<>COUNTIFS($T$4:$T$863,$T5,$D$4:$D$863,$D5,$F$4:$F$863,$F5,$G$4:$G$863,$G5,$K$4:$K$863,$K5,$M$4:$M$863,$M5),"⚠ INCOHÉRENT","") | AC5: =COUNTIFS($A$4:$A5,$A5,$J$4:$J5,$J5,$E$4:$E5,$E5) | AD5: =$A5&"|"&$J5&"|"&$E5&"|"&$AC5 | AE5: =IF($W5<>"","⚑ "&$W5&CHAR(10),"")&TEXT($F5,"hh:mm")&"-"&TEXT($G5,"hh:mm")&IF(OR($P5="Quinzaine A",AND($P5="Hebdo · groupes alternés",$C5="A"))," Q-A",IF(OR($P5="Quinzaine B",AND($P5="Hebdo · groupes alternés",$C5="B"))," Q-B",IF($P5="Exception"," PONCT.","")))&IF($X5="Oui"," OPT","")&CHAR(10)&$K5&CHAR(10)&$M5&IF($N5<>"",CHAR(10)&"Salle "&$N5,"")&IF($O5="En ligne",CHAR(10)&"EN LIGNE","")&IF($V5<>"",CHAR(10)&$V5,"") | AF5: 19h-20h30 Français (Hend) | AG5: du 14-09 jusquà le 20-09!G12
A6: S1 | B6: du 14 au 20 septembre 2026 | C6: A | D6: 46279 | E6: Lundi | F6: 0.8125 | G6: 0.875 | H6: =IF(OR($F6="",$G6=""),"",($G6-$F6)*24) | I6: Collège | J6: 7éme (B) | K6: Arabe | L6: Arabe | M6: Yahya | P6: Hebdomadaire | R6: 1 | S6: Oui | T6: S1-003 | U6: Original (septembre) | Y6: =IF($M6="","",IF(SUMPRODUCT(($D$4:$D$863=$D6)*($M$4:$M$863=$M6)*($T$4:$T$863<>$T6)*($F$4:$F$863<$G6)*($G$4:$G$863>$F6))>0,"⚠ CONFLIT","")) | Z6: =IF($J6="","",IF(SUMPRODUCT(($D$4:$D$863=$D6)*($J$4:$J$863=$J6)*($T$4:$T$863<>$T6)*($F$4:$F$863<$G6)*($G$4:$G$863>$F6)*(1-($X$4:$X$863="Oui")*($X6="Oui")))>0,"⚠ CONFLIT","")) | AA6: =IF(COUNTIFS($D$4:$D$863,$D6,$J$4:$J$863,$J6,$F$4:$F$863,$F6,$K$4:$K$863,$K6)>1,"⚠ DOUBLON","") | AB6: =IF(COUNTIF($T$4:$T$863,$T6)<>COUNTIFS($T$4:$T$863,$T6,$D$4:$D$863,$D6,$F$4:$F$863,$F6,$G$4:$G$863,$G6,$K$4:$K$863,$K6,$M$4:$M$863,$M6),"⚠ INCOHÉRENT","") | AC6: =COUNTIFS($A$4:$A6,$A6,$J$4:$J6,$J6,$E$4:$E6,$E6) | AD6: =$A6&"|"&$J6&"|"&$E6&"|"&$AC6 | AE6: =IF($W6<>"","⚑ "&$W6&CHAR(10),"")&TEXT($F6,"hh:mm")&"-"&TEXT($G6,"hh:mm")&IF(OR($P6="Quinzaine A",AND($P6="Hebdo · groupes alternés",$C6="A"))," Q-A",IF(OR($P6="Quinzaine B",AND($P6="Hebdo · groupes alternés",$C6="B"))," Q-B",IF($P6="Exception"," PONCT.","")))&IF($X6="Oui"," OPT","")&CHAR(10)&$K6&CHAR(10)&$M6&IF($N6<>"",CHAR(10)&"Salle "&$N6,"")&IF($O6="En ligne",CHAR(10)&"EN LIGNE","")&IF($V6<>"",CHAR(10)&$V6,"") | AF6: 19h30-21h Arabe (Yahya) | AG6: du 14-09 jusquà le 20-09!G23
A7: S1 | B7: du 14 au 20 septembre 2026 | C7: A | D7: 46279 | E7: Lundi | F7: 0.8125 | G7: 0.875 | H7: =IF(OR($F7="",$G7=""),"",($G7-$F7)*24) | I7: Collège | J7: 9éme (A) | K7: فيزياء | L7: Physique | M7: Melek | P7: Hebdomadaire | Q7: 9éme (A) + 9éme (B) + 9éme (C) | R7: 3 | S7: Oui | T7: S1-004 | U7: Original (septembre) | Y7: =IF($M7="","",IF(SUMPRODUCT(($D$4:$D$863=$D7)*($M$4:$M$863=$M7)*($T$4:$T$863<>$T7)*($F$4:$F$863<$G7)*($G$4:$G$863>$F7))>0,"⚠ CONFLIT","")) | Z7: =IF($J7="","",IF(SUMPRODUCT(($D$4:$D$863=$D7)*($J$4:$J$863=$J7)*($T$4:$T$863<>$T7)*($F$4:$F$863<$G7)*($G$4:$G$863>$F7)*(1-($X$4:$X$863="Oui")*($X7="Oui")))>0,"⚠ CONFLIT","")) | AA7: =IF(COUNTIFS($D$4:$D$863,$D7,$J$4:$J$863,$J7,$F$4:$F$863,$F7,$K$4:$K$863,$K7)>1,"⚠ DOUBLON","") | AB7: =IF(COUNTIF($T$4:$T$863,$T7)<>COUNTIFS($T$4:$T$863,$T7,$D$4:$D$863,$D7,$F$4:$F$863,$F7,$G$4:$G$863,$G7,$K$4:$K$863,$K7,$M$4:$M$863,$M7),"⚠ INCOHÉRENT","") | AC7: =COUNTIFS($A$4:$A7,$A7,$J$4:$J7,$J7,$E$4:$E7,$E7) | AD7: =$A7&"|"&$J7&"|"&$E7&"|"&$AC7 | AE7: =IF($W7<>"","⚑ "&$W7&CHAR(10),"")&TEXT($F7,"hh:mm")&"-"&TEXT($G7,"hh:mm")&IF(OR($P7="Quinzaine A",AND($P7="Hebdo · groupes alternés",$C7="A"))," Q-A",IF(OR($P7="Quinzaine B",AND($P7="Hebdo · groupes alternés",$C7="B"))," Q-B",IF($P7="Exception"," PONCT.","")))&IF($X7="Oui"," OPT","")&CHAR(10)&$K7&CHAR(10)&$M7&IF($N7<>"",CHAR(10)&"Salle "&$N7,"")&IF($O7="En ligne",CHAR(10)&"EN LIGNE","")&IF($V7<>"",CHAR(10)&$V7,"") | AF7: 19h30-21h فيزياء /par quinzaine (Melek) | AG7: du 14-09 jusquà le 20-09!G36
A8: S1 | B8: du 14 au 20 septembre 2026 | C8: A | D8: 46279 | E8: Lundi | F8: 0.8125 | G8: 0.875 | H8: =IF(OR($F8="",$G8=""),"",($G8-$F8)*24) | I8: Collège | J8: 9éme (B) | K8: فيزياء | L8: Physique | M8: Melek | P8: Hebdomadaire | Q8: 9éme (A) + 9éme (B) + 9éme (C) | R8: 3 | T8: S1-004 | U8: Original (septembre) | Y8: =IF($M8="","",IF(SUMPRODUCT(($D$4:$D$863=$D8)*($M$4:$M$863=$M8)*($T$4:$T$863<>$T8)*($F$4:$F$863<$G8)*($G$4:$G$863>$F8))>0,"⚠ CONFLIT","")) | Z8: =IF($J8="","",IF(SUMPRODUCT(($D$4:$D$863=$D8)*($J$4:$J$863=$J8)*($T$4:$T$863<>$T8)*($F$4:$F$863<$G8)*($G$4:$G$863>$F8)*(1-($X$4:$X$863="Oui")*($X8="Oui")))>0,"⚠ CONFLIT","")) | AA8: =IF(COUNTIFS($D$4:$D$863,$D8,$J$4:$J$863,$J8,$F$4:$F$863,$F8,$K$4:$K$863,$K8)>1,"⚠ DOUBLON","") | AB8: =IF(COUNTIF($T$4:$T$863,$T8)<>COUNTIFS($T$4:$T$863,$T8,$D$4:$D$863,$D8,$F$4:$F$863,$F8,$G$4:$G$863,$G8,$K$4:$K$863,$K8,$M$4:$M$863,$M8),"⚠ INCOHÉRENT","") | AC8: =COUNTIFS($A$4:$A8,$A8,$J$4:$J8,$J8,$E$4:$E8,$E8) | AD8: =$A8&"|"&$J8&"|"&$E8&"|"&$AC8 | AE8: =IF($W8<>"","⚑ "&$W8&CHAR(10),"")&TEXT($F8,"hh:mm")&"-"&TEXT($G8,"hh:mm")&IF(OR($P8="Quinzaine A",AND($P8="Hebdo · groupes alternés",$C8="A"))," Q-A",IF(OR($P8="Quinzaine B",AND($P8="Hebdo · groupes alternés",$C8="B"))," Q-B",IF($P8="Exception"," PONCT.","")))&IF($X8="Oui"," OPT","")&CHAR(10)&$K8&CHAR(10)&$M8&IF($N8<>"",CHAR(10)&"Salle "&$N8,"")&IF($O8="En ligne",CHAR(10)&"EN LIGNE","")&IF($V8<>"",CHAR(10)&$V8,"") | AF8: 19h30-21h فيزياء /par quinzaine (Melek) | AG8: du 14-09 jusquà le 20-09!G36
A9: S1 | B9: du 14 au 20 septembre 2026 | C9: A | D9: 46279 | E9: Lundi | F9: 0.8125 | G9: 0.875 | H9: =IF(OR($F9="",$G9=""),"",($G9-$F9)*24) | I9: Collège | J9: 9éme (C) | K9: فيزياء | L9: Physique | M9: Melek | P9: Hebdomadaire | Q9: 9éme (A) + 9éme (B) + 9éme (C) | R9: 3 | T9: S1-004 | U9: Original (septembre) | Y9: =IF($M9="","",IF(SUMPRODUCT(($D$4:$D$863=$D9)*($M$4:$M$863=$M9)*($T$4:$T$863<>$T9)*($F$4:$F$863<$G9)*($G$4:$G$863>$F9))>0,"⚠ CONFLIT","")) | Z9: =IF($J9="","",IF(SUMPRODUCT(($D$4:$D$863=$D9)*($J$4:$J$863=$J9)*($T$4:$T$863<>$T9)*($F$4:$F$863<$G9)*($G$4:$G$863>$F9)*(1-($X$4:$X$863="Oui")*($X9="Oui")))>0,"⚠ CONFLIT","")) | AA9: =IF(COUNTIFS($D$4:$D$863,$D9,$J$4:$J$863,$J9,$F$4:$F$863,$F9,$K$4:$K$863,$K9)>1,"⚠ DOUBLON","") | AB9: =IF(COUNTIF($T$4:$T$863,$T9)<>COUNTIFS($T$4:$T$863,$T9,$D$4:$D$863,$D9,$F$4:$F$863,$F9,$G$4:$G$863,$G9,$K$4:$K$863,$K9,$M$4:$M$863,$M9),"⚠ INCOHÉRENT","") | AC9: =COUNTIFS($A$4:$A9,$A9,$J$4:$J9,$J9,$E$4:$E9,$E9) | AD9: =$A9&"|"&$J9&"|"&$E9&"|"&$AC9 | AE9: =IF($W9<>"","⚑ "&$W9&CHAR(10),"")&TEXT($F9,"hh:mm")&"-"&TEXT($G9,"hh:mm")&IF(OR($P9="Quinzaine A",AND($P9="Hebdo · groupes alternés",$C9="A"))," Q-A",IF(OR($P9="Quinzaine B",AND($P9="Hebdo · groupes alternés",$C9="B"))," Q-B",IF($P9="Exception"," PONCT.","")))&IF($X9="Oui"," OPT","")&CHAR(10)&$K9&CHAR(10)&$M9&IF($N9<>"",CHAR(10)&"Salle "&$N9,"")&IF($O9="En ligne",CHAR(10)&"EN LIGNE","")&IF($V9<>"",CHAR(10)&$V9,"") | AF9: 19h30-21h فيزياء /par quinzaine (Melek) | AG9: du 14-09 jusquà le 20-09!G36
A10: S1 | B10: du 14 au 20 septembre 2026 | C10: A | D10: 46279 | E10: Lundi | F10: 0.8125 | G10: 0.875 | H10: =IF(OR($F10="",$G10=""),"",($G10-$F10)*24) | I10: Secondaire | J10: 1ére (A) | K10: Math | L10: Math | M10: Haythem | P10: Hebdomadaire | R10: 1 | S10: Oui | T10: S1-005 | U10: Original (septembre) | Y10: =IF($M10="","",IF(SUMPRODUCT(($D$4:$D$863=$D10)*($M$4:$M$863=$M10)*($T$4:$T$863<>$T10)*($F$4:$F$863<$G10)*($G$4:$G$863>$F10))>0,"⚠ CONFLIT","")) | Z10: =IF($J10="","",IF(SUMPRODUCT(($D$4:$D$863=$D10)*($J$4:$J$863=$J10)*($T$4:$T$863<>$T10)*($F$4:$F$863<$G10)*($G$4:$G$863>$F10)*(1-($X$4:$X$863="Oui")*($X10="Oui")))>0,"⚠ CONFLIT","")) | AA10: =IF(COUNTIFS($D$4:$D$863,$D10,$J$4:$J$863,$J10,$F$4:$F$863,$F10,$K$4:$K$863,$K10)>1,"⚠ DOUBLON","") | AB10: =IF(COUNTIF($T$4:$T$863,$T10)<>COUNTIFS($T$4:$T$863,$T10,$D$4:$D$863,$D10,$F$4:$F$863,$F10,$G$4:$G$863,$G10,$K$4:$K$863,$K10,$M$4:$M$863,$M10),"⚠ INCOHÉRENT","") | AC10: =COUNTIFS($A$4:$A10,$A10,$J$4:$J10,$J10,$E$4:$E10,$E10) | AD10: =$A10&"|"&$J10&"|"&$E10&"|"&$AC10 | AE10: =IF($W10<>"","⚑ "&$W10&CHAR(10),"")&TEXT($F10,"hh:mm")&"-"&TEXT($G10,"hh:mm")&IF(OR($P10="Quinzaine A",AND($P10="Hebdo · groupes alternés",$C10="A"))," Q-A",IF(OR($P10="Quinzaine B",AND($P10="Hebdo · groupes alternés",$C10="B"))," Q-B",IF($P10="Exception"," PONCT.","")))&IF($X10="Oui"," OPT","")&CHAR(10)&$K10&CHAR(10)&$M10&IF($N10<>"",CHAR(10)&"Salle "&$N10,"")&IF($O10="En ligne",CHAR(10)&"EN LIGNE","")&IF($V10<>"",CHAR(10)&$V10,"") | AF10: 19h30-21h Math (Haythem) | AG10: du 14-09 jusquà le 20-09!G48
A11: S1 | B11: du 14 au 20 septembre 2026 | C11: A | D11: 46279 | E11: Lundi | F11: 0.79166667 | G11: 0.875 | H11: =IF(OR($F11="",$G11=""),"",($G11-$F11)*24) | I11: Secondaire | J11: 2éme INFO | K11: Informatique | L11: Informatique | M11: Aymen | P11: Ponctuelle / modifiée | R11: 1 | S11: Oui | T11: S1-006 | U11: Original (septembre) | Y11: =IF($M11="","",IF(SUMPRODUCT(($D$4:$D$863=$D11)*($M$4:$M$863=$M11)*($T$4:$T$863<>$T11)*($F$4:$F$863<$G11)*($G$4:$G$863>$F11))>0,"⚠ CONFLIT","")) | Z11: =IF($J11="","",IF(SUMPRODUCT(($D$4:$D$863=$D11)*($J$4:$J$863=$J11)*($T$4:$T$863<>$T11)*($F$4:$F$863<$G11)*($G$4:$G$863>$F11)*(1-($X$4:$X$863="Oui")*($X11="Oui")))>0,"⚠ CONFLIT","")) | AA11: =IF(COUNTIFS($D$4:$D$863,$D11,$J$4:$J$863,$J11,$F$4:$F$863,$F11,$K$4:$K$863,$K11)>1,"⚠ DOUBLON","") | AB11: =IF(COUNTIF($T$4:$T$863,$T11)<>COUNTIFS($T$4:$T$863,$T11,$D$4:$D$863,$D11,$F$4:$F$863,$F11,$G$4:$G$863,$G11,$K$4:$K$863,$K11,$M$4:$M$863,$M11),"⚠ INCOHÉRENT","") | AC11: =COUNTIFS($A$4:$A11,$A11,$J$4:$J11,$J11,$E$4:$E11,$E11) | AD11: =$A11&"|"&$J11&"|"&$E11&"|"&$AC11 | AE11: =IF($W11<>"","⚑ "&$W11&CHAR(10),"")&TEXT($F11,"hh:mm")&"-"&TEXT($G11,"hh:mm")&IF(OR($P11="Quinzaine A",AND($P11="Hebdo · groupes alternés",$C11="A"))," Q-A",IF(OR($P11="Quinzaine B",AND($P11="Hebdo · groupes alternés",$C11="B"))," Q-B",IF($P11="Exception"," PONCT.","")))&IF($X11="Oui"," OPT","")&CHAR(10)&$K11&CHAR(10)&$M11&IF($N11<>"",CHAR(10)&"Salle "&$N11,"")&IF($O11="En ligne",CHAR(10)&"EN LIGNE","")&IF($V11<>"",CHAR(10)&$V11,"") | AF11: 19h-21h Informatique (Aymen) | AG11: du 14-09 jusquà le 20-09!G60
A12: S1 | B12: du 14 au 20 septembre 2026 | C12: A | D12: 46279 | E12: Lundi | F12: 0.79166667 | G12: 0.875 | H12: =IF(OR($F12="",$G12=""),"",($G12-$F12)*24) | I12: Bac | J12: Bac Eco | K12: Gestion | L12: Gestion | M12: Yassine | P12: Hebdomadaire | R12: 1 | S12: Oui | T12: S1-007 | U12: Original (septembre) | Y12: =IF($M12="","",IF(SUMPRODUCT(($D$4:$D$863=$D12)*($M$4:$M$863=$M12)*($T$4:$T$863<>$T12)*($F$4:$F$863<$G12)*($G$4:$G$863>$F12))>0,"⚠ CONFLIT","")) | Z12: =IF($J12="","",IF(SUMPRODUCT(($D$4:$D$863=$D12)*($J$4:$J$863=$J12)*($T$4:$T$863<>$T12)*($F$4:$F$863<$G12)*($G$4:$G$863>$F12)*(1-($X$4:$X$863="Oui")*($X12="Oui")))>0,"⚠ CONFLIT","")) | AA12: =IF(COUNTIFS($D$4:$D$863,$D12,$J$4:$J$863,$J12,$F$4:$F$863,$F12,$K$4:$K$863,$K12)>1,"⚠ DOUBLON","") | AB12: =IF(COUNTIF($T$4:$T$863,$T12)<>COUNTIFS($T$4:$T$863,$T12,$D$4:$D$863,$D12,$F$4:$F$863,$F12,$G$4:$G$863,$G12,$K$4:$K$863,$K12,$M$4:$M$863,$M12),"⚠ INCOHÉRENT","") | AC12: =COUNTIFS($A$4:$A12,$A12,$J$4:$J12,$J12,$E$4:$E12,$E12) | AD12: =$A12&"|"&$J12&"|"&$E12&"|"&$AC12 | AE12: =IF($W12<>"","⚑ "&$W12&CHAR(10),"")&TEXT($F12,"hh:mm")&"-"&TEXT($G12,"hh:mm")&IF(OR($P12="Quinzaine A",AND($P12="Hebdo · groupes alternés",$C12="A"))," Q-A",IF(OR($P12="Quinzaine B",AND($P12="Hebdo · groupes alternés",$C12="B"))," Q-B",IF($P12="Exception"," PONCT.","")))&IF($X12="Oui"," OPT","")&CHAR(10)&$K12&CHAR(10)&$M12&IF($N12<>"",CHAR(10)&"Salle "&$N12,"")&IF($O12="En ligne",CHAR(10)&"EN LIGNE","")&IF($V12<>"",CHAR(10)&$V12,"") | AF12: 19h-21h Gestion (Yassine) | AG12: du 14-09 jusquà le 20-09!G68
A13: S1 | B13: du 14 au 20 septembre 2026 | C13: A | D13: 46279 | E13: Lundi | F13: 0.79166667 | G13: 0.875 | H13: =IF(OR($F13="",$G13=""),"",($G13-$F13)*24) | I13: Bac | J13: Bac SCE | K13: Physique | L13: Physique | M13: Sondes | P13: Hebdomadaire | R13: 1 | S13: Oui | T13: S1-008 | U13: Original (septembre) | Y13: =IF($M13="","",IF(SUMPRODUCT(($D$4:$D$863=$D13)*($M$4:$M$863=$M13)*($T$4:$T$863<>$T13)*($F$4:$F$863<$G13)*($G$4:$G$863>$F13))>0,"⚠ CONFLIT","")) | Z13: =IF($J13="","",IF(SUMPRODUCT(($D$4:$D$863=$D13)*($J$4:$J$863=$J13)*($T$4:$T$863<>$T13)*($F$4:$F$863<$G13)*($G$4:$G$863>$F13)*(1-($X$4:$X$863="Oui")*($X13="Oui")))>0,"⚠ CONFLIT","")) | AA13: =IF(COUNTIFS($D$4:$D$863,$D13,$J$4:$J$863,$J13,$F$4:$F$863,$F13,$K$4:$K$863,$K13)>1,"⚠ DOUBLON","") | AB13: =IF(COUNTIF($T$4:$T$863,$T13)<>COUNTIFS($T$4:$T$863,$T13,$D$4:$D$863,$D13,$F$4:$F$863,$F13,$G$4:$G$863,$G13,$K$4:$K$863,$K13,$M$4:$M$863,$M13),"⚠ INCOHÉRENT","") | AC13: =COUNTIFS($A$4:$A13,$A13,$J$4:$J13,$J13,$E$4:$E13,$E13) | AD13: =$A13&"|"&$J13&"|"&$E13&"|"&$AC13 | AE13: =IF($W13<>"","⚑ "&$W13&CHAR(10),"")&TEXT($F13,"hh:mm")&"-"&TEXT($G13,"hh:mm")&IF(OR($P13="Quinzaine A",AND($P13="Hebdo · groupes alternés",$C13="A"))," Q-A",IF(OR($P13="Quinzaine B",AND($P13="Hebdo · groupes alternés",$C13="B"))," Q-B",IF($P13="Exception"," PONCT.","")))&IF($X13="Oui"," OPT","")&CHAR(10)&$K13&CHAR(10)&$M13&IF($N13<>"",CHAR(10)&"Salle "&$N13,"")&IF($O13="En ligne",CHAR(10)&"EN LIGNE","")&IF($V13<>"",CHAR(10)&$V13,"") | AF13: 19h-21h Physique (Sondes) | AG13: du 14-09 jusquà le 20-09!G74
A14: S1 | B14: du 14 au 20 septembre 2026 | C14: A | D14: 46279 | E14: Lundi | F14: 0.8125 | G14: 0.875 | H14: =IF(OR($F14="",$G14=""),"",($G14-$F14)*24) | I14: Bac | J14: Bac INFO | K14: Physique | L14: Physique | M14: Samia | P14: Hebdomadaire | R14: 1 | S14: Oui | T14: S1-009 | U14: Original (septembre) | Y14: =IF($M14="","",IF(SUMPRODUCT(($D$4:$D$863=$D14)*($M$4:$M$863=$M14)*($T$4:$T$863<>$T14)*($F$4:$F$863<$G14)*($G$4:$G$863>$F14))>0,"⚠ CONFLIT","")) | Z14: =IF($J14="","",IF(SUMPRODUCT(($D$4:$D$863=$D14)*($J$4:$J$863=$J14)*($T$4:$T$863<>$T14)*($F$4:$F$863<$G14)*($G$4:$G$863>$F14)*(1-($X$4:$X$863="Oui")*($X14="Oui")))>0,"⚠ CONFLIT","")) | AA14: =IF(COUNTIFS($D$4:$D$863,$D14,$J$4:$J$863,$J14,$F$4:$F$863,$F14,$K$4:$K$863,$K14)>1,"⚠ DOUBLON","") | AB14: =IF(COUNTIF($T$4:$T$863,$T14)<>COUNTIFS($T$4:$T$863,$T14,$D$4:$D$863,$D14,$F$4:$F$863,$F14,$G$4:$G$863,$G14,$K$4:$K$863,$K14,$M$4:$M$863,$M14),"⚠ INCOHÉRENT","") | AC14: =COUNTIFS($A$4:$A14,$A14,$J$4:$J14,$J14,$E$4:$E14,$E14) | AD14: =$A14&"|"&$J14&"|"&$E14&"|"&$AC14 | AE14: =IF($W14<>"","⚑ "&$W14&CHAR(10),"")&TEXT($F14,"hh:mm")&"-"&TEXT($G14,"hh:mm")&IF(OR($P14="Quinzaine A",AND($P14="Hebdo · groupes alternés",$C14="A"))," Q-A",IF(OR($P14="Quinzaine B",AND($P14="Hebdo · groupes alternés",$C14="B"))," Q-B",IF($P14="Exception"," PONCT.","")))&IF($X14="Oui"," OPT","")&CHAR(10)&$K14&CHAR(10)&$M14&IF($N14<>"",CHAR(10)&"Salle "&$N14,"")&IF($O14="En ligne",CHAR(10)&"EN LIGNE","")&IF($V14<>"",CHAR(10)&$V14,"") | AF14: 19h30-21h Physique (Samia) | AG14: du 14-09 jusquà le 20-09!G78
A15: S1 | B15: du 14 au 20 septembre 2026 | C15: A | D15: 46280 | E15: Mardi | F15: 0.79166667 | G15: 0.875 | H15: =IF(OR($F15="",$G15=""),"",($G15-$F15)*24) | I15: Primaire | J15: 5éme | K15: عربية | L15: Arabe | M15: Lobna | P15: Hebdomadaire | R15: 1 | S15: Oui | T15: S1-010 | U15: Original (septembre) | Y15: =IF($M15="","",IF(SUMPRODUCT(($D$4:$D$863=$D15)*($M$4:$M$863=$M15)*($T$4:$T$863<>$T15)*($F$4:$F$863<$G15)*($G$4:$G$863>$F15))>0,"⚠ CONFLIT","")) | Z15: =IF($J15="","",IF(SUMPRODUCT(($D$4:$D$863=$D15)*($J$4:$J$863=$J15)*($T$4:$T$863<>$T15)*($F$4:$F$863<$G15)*($G$4:$G$863>$F15)*(1-($X$4:$X$863="Oui")*($X15="Oui")))>0,"⚠ CONFLIT","")) | AA15: =IF(COUNTIFS($D$4:$D$863,$D15,$J$4:$J$863,$J15,$F$4:$F$863,$F15,$K$4:$K$863,$K15)>1,"⚠ DOUBLON","") | AB15: =IF(COUNTIF($T$4:$T$863,$T15)<>COUNTIFS($T$4:$T$863,$T15,$D$4:$D$863,$D15,$F$4:$F$863,$F15,$G$4:$G$863,$G15,$K$4:$K$863,$K15,$M$4:$M$863,$M15),"⚠ INCOHÉRENT","") | AC15: =COUNTIFS($A$4:$A15,$A15,$J$4:$J15,$J15,$E$4:$E15,$E15) | AD15: =$A15&"|"&$J15&"|"&$E15&"|"&$AC15 | AE15: =IF($W15<>"","⚑ "&$W15&CHAR(10),"")&TEXT($F15,"hh:mm")&"-"&TEXT($G15,"hh:mm")&IF(OR($P15="Quinzaine A",AND($P15="Hebdo · groupes alternés",$C15="A"))," Q-A",IF(OR($P15="Quinzaine B",AND($P15="Hebdo · groupes alternés",$C15="B"))," Q-B",IF($P15="Exception"," PONCT.","")))&IF($X15="Oui"," OPT","")&CHAR(10)&$K15&CHAR(10)&$M15&IF($N15<>"",CHAR(10)&"Salle "&$N15,"")&IF($O15="En ligne",CHAR(10)&"EN LIGNE","")&IF($V15<>"",CHAR(10)&$V15,"") | AF15: 19h-21h عربية (Lobna) | AG15: du 14-09 jusquà le 20-09!H6
A16: S1 | B16: du 14 au 20 septembre 2026 | C16: A | D16: 46280 | E16: Mardi | F16: 0.79166667 | G16: 0.85416667 | H16: =IF(OR($F16="",$G16=""),"",($G16-$F16)*24) | I16: Primaire | J16: 6éme (B) | K16: Français | L16: Français | M16: Hend | P16: Hebdomadaire | R16: 1 | S16: Oui | T16: S1-011 | U16: Original (septembre) | Y16: =IF($M16="","",IF(SUMPRODUCT(($D$4:$D$863=$D16)*($M$4:$M$863=$M16)*($T$4:$T$863<>$T16)*($F$4:$F$863<$G16)*($G$4:$G$863>$F16))>0,"⚠ CONFLIT","")) | Z16: =IF($J16="","",IF(SUMPRODUCT(($D$4:$D$863=$D16)*($J$4:$J$863=$J16)*($T$4:$T$863<>$T16)*($F$4:$F$863<$G16)*($G$4:$G$863>$F16)*(1-($X$4:$X$863="Oui")*($X16="Oui")))>0,"⚠ CONFLIT","")) | AA16: =IF(COUNTIFS($D$4:$D$863,$D16,$J$4:$J$863,$J16,$F$4:$F$863,$F16,$K$4:$K$863,$K16)>1,"⚠ DOUBLON","") | AB16: =IF(COUNTIF($T$4:$T$863,$T16)<>COUNTIFS($T$4:$T$863,$T16,$D$4:$D$863,$D16,$F$4:$F$863,$F16,$G$4:$G$863,$G16,$K$4:$K$863,$K16,$M$4:$M$863,$M16),"⚠ INCOHÉRENT","") | AC16: =COUNTIFS($A$4:$A16,$A16,$J$4:$J16,$J16,$E$4:$E16,$E16) | AD16: =$A16&"|"&$J16&"|"&$E16&"|"&$AC16 | AE16: =IF($W16<>"","⚑ "&$W16&CHAR(10),"")&TEXT($F16,"hh:mm")&"-"&TEXT($G16,"hh:mm")&IF(OR($P16="Quinzaine A",AND($P16="Hebdo · groupes alternés",$C16="A"))," Q-A",IF(OR($P16="Quinzaine B",AND($P16="Hebdo · groupes alternés",$C16="B"))," Q-B",IF($P16="Exception"," PONCT.","")))&IF($X16="Oui"," OPT","")&CHAR(10)&$K16&CHAR(10)&$M16&IF($N16<>"",CHAR(10)&"Salle "&$N16,"")&IF($O16="En ligne",CHAR(10)&"EN LIGNE","")&IF($V16<>"",CHAR(10)&$V16,"") | AF16: 19h-20h30 Français (Hend) | AG16: du 14-09 jusquà le 20-09!H16
A17: S1 | B17: du 14 au 20 septembre 2026 | C17: A | D17: 46280 | E17: Mardi | F17: 0.79166667 | G17: 0.85416667 | H17: =IF(OR($F17="",$G17=""),"",($G17-$F17)*24) | I17: Collège | J17: 7éme (A) | K17: Anglais | L17: Anglais | M17: Imen Ben Lazrak | P17: Hebdo · groupes alternés | R17: 1 | S17: Oui | T17: S1-012 | U17: Original (septembre) | Y17: =IF($M17="","",IF(SUMPRODUCT(($D$4:$D$863=$D17)*($M$4:$M$863=$M17)*($T$4:$T$863<>$T17)*($F$4:$F$863<$G17)*($G$4:$G$863>$F17))>0,"⚠ CONFLIT","")) | Z17: =IF($J17="","",IF(SUMPRODUCT(($D$4:$D$863=$D17)*($J$4:$J$863=$J17)*($T$4:$T$863<>$T17)*($F$4:$F$863<$G17)*($G$4:$G$863>$F17)*(1-($X$4:$X$863="Oui")*($X17="Oui")))>0,"⚠ CONFLIT","")) | AA17: =IF(COUNTIFS($D$4:$D$863,$D17,$J$4:$J$863,$J17,$F$4:$F$863,$F17,$K$4:$K$863,$K17)>1,"⚠ DOUBLON","") | AB17: =IF(COUNTIF($T$4:$T$863,$T17)<>COUNTIFS($T$4:$T$863,$T17,$D$4:$D$863,$D17,$F$4:$F$863,$F17,$G$4:$G$863,$G17,$K$4:$K$863,$K17,$M$4:$M$863,$M17),"⚠ INCOHÉRENT","") | AC17: =COUNTIFS($A$4:$A17,$A17,$J$4:$J17,$J17,$E$4:$E17,$E17) | AD17: =$A17&"|"&$J17&"|"&$E17&"|"&$AC17 | AE17: =IF($W17<>"","⚑ "&$W17&CHAR(10),"")&TEXT($F17,"hh:mm")&"-"&TEXT($G17,"hh:mm")&IF(OR($P17="Quinzaine A",AND($P17="Hebdo · groupes alternés",$C17="A"))," Q-A",IF(OR($P17="Quinzaine B",AND($P17="Hebdo · groupes alternés",$C17="B"))," Q-B",IF($P17="Exception"," PONCT.","")))&IF($X17="Oui"," OPT","")&CHAR(10)&$K17&CHAR(10)&$M17&IF($N17<>"",CHAR(10)&"Salle "&$N17,"")&IF($O17="En ligne",CHAR(10)&"EN LIGNE","")&IF($V17<>"",CHAR(10)&$V17,"") | AF17: 19h-20h30 Anglais /par quinzaine (Imen Ben Lazrak) | AG17: du 14-09 jusquà le 20-09!H19
A18: S1 | B18: du 14 au 20 septembre 2026 | C18: A | D18: 46280 | E18: Mardi | F18: 0.8125 | G18: 0.875 | H18: =IF(OR($F18="",$G18=""),"",($G18-$F18)*24) | I18: Collège | J18: 8éme (B) | K18: Arabe | L18: Arabe | M18: Yahya | P18: Hebdomadaire | Q18: 8éme (B) + 8éme (C) | R18: 2 | S18: Oui | T18: S1-013 | U18: Original (septembre) | Y18: =IF($M18="","",IF(SUMPRODUCT(($D$4:$D$863=$D18)*($M$4:$M$863=$M18)*($T$4:$T$863<>$T18)*($F$4:$F$863<$G18)*($G$4:$G$863>$F18))>0,"⚠ CONFLIT","")) | Z18: =IF($J18="","",IF(SUMPRODUCT(($D$4:$D$863=$D18)*($J$4:$J$863=$J18)*($T$4:$T$863<>$T18)*($F$4:$F$863<$G18)*($G$4:$G$863>$F18)*(1-($X$4:$X$863="Oui")*($X18="Oui")))>0,"⚠ CONFLIT","")) | AA18: =IF(COUNTIFS($D$4:$D$863,$D18,$J$4:$J$863,$J18,$F$4:$F$863,$F18,$K$4:$K$863,$K18)>1,"⚠ DOUBLON","") | AB18: =IF(COUNTIF($T$4:$T$863,$T18)<>COUNTIFS($T$4:$T$863,$T18,$D$4:$D$863,$D18,$F$4:$F$863,$F18,$G$4:$G$863,$G18,$K$4:$K$863,$K18,$M$4:$M$863,$M18),"⚠ INCOHÉRENT","") | AC18: =COUNTIFS($A$4:$A18,$A18,$J$4:$J18,$J18,$E$4:$E18,$E18) | AD18: =$A18&"|"&$J18&"|"&$E18&"|"&$AC18 | AE18: =IF($W18<>"","⚑ "&$W18&CHAR(10),"")&TEXT($F18,"hh:mm")&"-"&TEXT($G18,"hh:mm")&IF(OR($P18="Quinzaine A",AND($P18="Hebdo · groupes alternés",$C18="A"))," Q-A",IF(OR($P18="Quinzaine B",AND($P18="Hebdo · groupes alternés",$C18="B"))," Q-B",IF($P18="Exception"," PONCT.","")))&IF($X18="Oui"," OPT","")&CHAR(10)&$K18&CHAR(10)&$M18&IF($N18<>"",CHAR(10)&"Salle "&$N18,"")&IF($O18="En ligne",CHAR(10)&"EN LIGNE","")&IF($V18<>"",CHAR(10)&$V18,"") | AF18: 19h30-21h Arabe (Yahya) | AG18: du 14-09 jusquà le 20-09!H31
A19: S1 | B19: du 14 au 20 septembre 2026 | C19: A | D19: 46280 | E19: Mardi | F19: 0.8125 | G19: 0.875 | H19: =IF(OR($F19="",$G19=""),"",($G19-$F19)*24) | I19: Collège | J19: 8éme (C) | K19: Arabe | L19: Arabe | M19: Yahya | P19: Hebdomadaire | Q19: 8éme (B) + 8éme (C) | R19: 2 | T19: S1-013 | U19: Original (septembre) | Y19: =IF($M19="","",IF(SUMPRODUCT(($D$4:$D$863=$D19)*($M$4:$M$863=$M19)*($T$4:$T$863<>$T19)*($F$4:$F$863<$G19)*($G$4:$G$863>$F19))>0,"⚠ CONFLIT","")) | Z19: =IF($J19="","",IF(SUMPRODUCT(($D$4:$D$863=$D19)*($J$4:$J$863=$J19)*($T$4:$T$863<>$T19)*($F$4:$F$863<$G19)*($G$4:$G$863>$F19)*(1-($X$4:$X$863="Oui")*($X19="Oui")))>0,"⚠ CONFLIT","")) | AA19: =IF(COUNTIFS($D$4:$D$863,$D19,$J$4:$J$863,$J19,$F$4:$F$863,$F19,$K$4:$K$863,$K19)>1,"⚠ DOUBLON","") | AB19: =IF(COUNTIF($T$4:$T$863,$T19)<>COUNTIFS($T$4:$T$863,$T19,$D$4:$D$863,$D19,$F$4:$F$863,$F19,$G$4:$G$863,$G19,$K$4:$K$863,$K19,$M$4:$M$863,$M19),"⚠ INCOHÉRENT","") | AC19: =COUNTIFS($A$4:$A19,$A19,$J$4:$J19,$J19,$E$4:$E19,$E19) | AD19: =$A19&"|"&$J19&"|"&$E19&"|"&$AC19 | AE19: =IF($W19<>"","⚑ "&$W19&CHAR(10),"")&TEXT($F19,"hh:mm")&"-"&TEXT($G19,"hh:mm")&IF(OR($P19="Quinzaine A",AND($P19="Hebdo · groupes alternés",$C19="A"))," Q-A",IF(OR($P19="Quinzaine B",AND($P19="Hebdo · groupes alternés",$C19="B"))," Q-B",IF($P19="Exception"," PONCT.","")))&IF($X19="Oui"," OPT","")&CHAR(10)&$K19&CHAR(10)&$M19&IF($N19<>"",CHAR(10)&"Salle "&$N19,"")&IF($O19="En ligne",CHAR(10)&"EN LIGNE","")&IF($V19<>"",CHAR(10)&$V19,"") | AF19: 19h30-21h Arabe (Yahya) | AG19: du 14-09 jusquà le 20-09!H31
A20: S1 | B20: du 14 au 20 septembre 2026 | C20: A | D20: 46280 | E20: Mardi | F20: 0.79166667 | G20: 0.85416667 | H20: =IF(OR($F20="",$G20=""),"",($G20-$F20)*24) | I20: Collège | J20: 9éme (A) | K20: Math | L20: Math | M20: Faouzi | P20: Hebdomadaire | R20: 1 | S20: Oui | T20: S1-014 | U20: Original (septembre) | Y20: =IF($M20="","",IF(SUMPRODUCT(($D$4:$D$863=$D20)*($M$4:$M$863=$M20)*($T$4:$T$863<>$T20)*($F$4:$F$863<$G20)*($G$4:$G$863>$F20))>0,"⚠ CONFLIT","")) | Z20: =IF($J20="","",IF(SUMPRODUCT(($D$4:$D$863=$D20)*($J$4:$J$863=$J20)*($T$4:$T$863<>$T20)*($F$4:$F$863<$G20)*($G$4:$G$863>$F20)*(1-($X$4:$X$863="Oui")*($X20="Oui")))>0,"⚠ CONFLIT","")) | AA20: =IF(COUNTIFS($D$4:$D$863,$D20,$J$4:$J$863,$J20,$F$4:$F$863,$F20,$K$4:$K$863,$K20)>1,"⚠ DOUBLON","") | AB20: =IF(COUNTIF($T$4:$T$863,$T20)<>COUNTIFS($T$4:$T$863,$T20,$D$4:$D$863,$D20,$F$4:$F$863,$F20,$G$4:$G$863,$G20,$K$4:$K$863,$K20,$M$4:$M$863,$M20),"⚠ INCOHÉRENT","") | AC20: =COUNTIFS($A$4:$A20,$A20,$J$4:$J20,$J20,$E$4:$E20,$E20) | AD20: =$A20&"|"&$J20&"|"&$E20&"|"&$AC20 | AE20: =IF($W20<>"","⚑ "&$W20&CHAR(10),"")&TEXT($F20,"hh:mm")&"-"&TEXT($G20,"hh:mm")&IF(OR($P20="Quinzaine A",AND($P20="Hebdo · groupes alternés",$C20="A"))," Q-A",IF(OR($P20="Quinzaine B",AND($P20="Hebdo · groupes alternés",$C20="B"))," Q-B",IF($P20="Exception"," PONCT.","")))&IF($X20="Oui"," OPT","")&CHAR(10)&$K20&CHAR(10)&$M20&IF($N20<>"",CHAR(10)&"Salle "&$N20,"")&IF($O20="En ligne",CHAR(10)&"EN LIGNE","")&IF($V20<>"",CHAR(10)&$V20,"") | AF20: 19h-20h30 Math (Faouzi) | AG20: du 14-09 jusquà le 20-09!H36
A21: S1 | B21: du 14 au 20 septembre 2026 | C21: A | D21: 46280 | E21: Mardi | F21: 0.80208333 | G21: 0.86458333 | H21: =IF(OR($F21="",$G21=""),"",($G21-$F21)*24) | I21: Collège | J21: 9éme (B) | K21: SVT | L21: SVT | M21: Imen Jribi | P21: Hebdomadaire | R21: 1 | S21: Oui | T21: S1-015 | U21: Original (septembre) | Y21: =IF($M21="","",IF(SUMPRODUCT(($D$4:$D$863=$D21)*($M$4:$M$863=$M21)*($T$4:$T$863<>$T21)*($F$4:$F$863<$G21)*($G$4:$G$863>$F21))>0,"⚠ CONFLIT","")) | Z21: =IF($J21="","",IF(SUMPRODUCT(($D$4:$D$863=$D21)*($J$4:$J$863=$J21)*($T$4:$T$863<>$T21)*($F$4:$F$863<$G21)*($G$4:$G$863>$F21)*(1-($X$4:$X$863="Oui")*($X21="Oui")))>0,"⚠ CONFLIT","")) | AA21: =IF(COUNTIFS($D$4:$D$863,$D21,$J$4:$J$863,$J21,$F$4:$F$863,$F21,$K$4:$K$863,$K21)>1,"⚠ DOUBLON","") | AB21: =IF(COUNTIF($T$4:$T$863,$T21)<>COUNTIFS($T$4:$T$863,$T21,$D$4:$D$863,$D21,$F$4:$F$863,$F21,$G$4:$G$863,$G21,$K$4:$K$863,$K21,$M$4:$M$863,$M21),"⚠ INCOHÉRENT","") | AC21: =COUNTIFS($A$4:$A21,$A21,$J$4:$J21,$J21,$E$4:$E21,$E21) | AD21: =$A21&"|"&$J21&"|"&$E21&"|"&$AC21 | AE21: =IF($W21<>"","⚑ "&$W21&CHAR(10),"")&TEXT($F21,"hh:mm")&"-"&TEXT($G21,"hh:mm")&IF(OR($P21="Quinzaine A",AND($P21="Hebdo · groupes alternés",$C21="A"))," Q-A",IF(OR($P21="Quinzaine B",AND($P21="Hebdo · groupes alternés",$C21="B"))," Q-B",IF($P21="Exception"," PONCT.","")))&IF($X21="Oui"," OPT","")&CHAR(10)&$K21&CHAR(10)&$M21&IF($N21<>"",CHAR(10)&"Salle "&$N21,"")&IF($O21="En ligne",CHAR(10)&"EN LIGNE","")&IF($V21<>"",CHAR(10)&$V21,"") | AF21: 19h15-20h45 SVT (Imen Jribi) | AG21: du 14-09 jusquà le 20-09!H43
A22: S1 | B22: du 14 au 20 septembre 2026 | C22: A | D22: 46280 | E22: Mardi | F22: 0.8125 | G22: 0.875 | H22: =IF(OR($F22="",$G22=""),"",($G22-$F22)*24) | I22: Secondaire | J22: 1ére (A) | K22: Français | L22: Français | M22: Nassima | P22: Hebdomadaire | R22: 1 | S22: Oui | T22: S1-016 | U22: Original (septembre) | Y22: =IF($M22="","",IF(SUMPRODUCT(($D$4:$D$863=$D22)*($M$4:$M$863=$M22)*($T$4:$T$863<>$T22)*($F$4:$F$863<$G22)*($G$4:$G$863>$F22))>0,"⚠ CONFLIT","")) | Z22: =IF($J22="","",IF(SUMPRODUCT(($D$4:$D$863=$D22)*($J$4:$J$863=$J22)*($T$4:$T$863<>$T22)*($F$4:$F$863<$G22)*($G$4:$G$863>$F22)*(1-($X$4:$X$863="Oui")*($X22="Oui")))>0,"⚠ CONFLIT","")) | AA22: =IF(COUNTIFS($D$4:$D$863,$D22,$J$4:$J$863,$J22,$F$4:$F$863,$F22,$K$4:$K$863,$K22)>1,"⚠ DOUBLON","") | AB22: =IF(COUNTIF($T$4:$T$863,$T22)<>COUNTIFS($T$4:$T$863,$T22,$D$4:$D$863,$D22,$F$4:$F$863,$F22,$G$4:$G$863,$G22,$K$4:$K$863,$K22,$M$4:$M$863,$M22),"⚠ INCOHÉRENT","") | AC22: =COUNTIFS($A$4:$A22,$A22,$J$4:$J22,$J22,$E$4:$E22,$E22) | AD22: =$A22&"|"&$J22&"|"&$E22&"|"&$AC22 | AE22: =IF($W22<>"","⚑ "&$W22&CHAR(10),"")&TEXT($F22,"hh:mm")&"-"&TEXT($G22,"hh:mm")&IF(OR($P22="Quinzaine A",AND($P22="Hebdo · groupes alternés",$C22="A"))," Q-A",IF(OR($P22="Quinzaine B",AND($P22="Hebdo · groupes alternés",$C22="B"))," Q-B",IF($P22="Exception"," PONCT.","")))&IF($X22="Oui"," OPT","")&CHAR(10)&$K22&CHAR(10)&$M22&IF($N22<>"",CHAR(10)&"Salle "&$N22,"")&IF($O22="En ligne",CHAR(10)&"EN LIGNE","")&IF($V22<>"",CHAR(10)&$V22,"") | AF22: 19h30-21h Français (Nassima) | AG22: du 14-09 jusquà le 20-09!H48
A23: S1 | B23: du 14 au 20 septembre 2026 | C23: A | D23: 46280 | E23: Mardi | F23: 0.8125 | G23: 0.875 | H23: =IF(OR($F23="",$G23=""),"",($G23-$F23)*24) | I23: Secondaire | J23: 1ére (B) | K23: Math | L23: Math | M23: Haythem | P23: Hebdomadaire | R23: 1 | S23: Oui | T23: S1-017 | U23: Original (septembre) | Y23: =IF($M23="","",IF(SUMPRODUCT(($D$4:$D$863=$D23)*($M$4:$M$863=$M23)*($T$4:$T$863<>$T23)*($F$4:$F$863<$G23)*($G$4:$G$863>$F23))>0,"⚠ CONFLIT","")) | Z23: =IF($J23="","",IF(SUMPRODUCT(($D$4:$D$863=$D23)*($J$4:$J$863=$J23)*($T$4:$T$863<>$T23)*($F$4:$F$863<$G23)*($G$4:$G$863>$F23)*(1-($X$4:$X$863="Oui")*($X23="Oui")))>0,"⚠ CONFLIT","")) | AA23: =IF(COUNTIFS($D$4:$D$863,$D23,$J$4:$J$863,$J23,$F$4:$F$863,$F23,$K$4:$K$863,$K23)>1,"⚠ DOUBLON","") | AB23: =IF(COUNTIF($T$4:$T$863,$T23)<>COUNTIFS($T$4:$T$863,$T23,$D$4:$D$863,$D23,$F$4:$F$863,$F23,$G$4:$G$863,$G23,$K$4:$K$863,$K23,$M$4:$M$863,$M23),"⚠ INCOHÉRENT","") | AC23: =COUNTIFS($A$4:$A23,$A23,$J$4:$J23,$J23,$E$4:$E23,$E23) | AD23: =$A23&"|"&$J23&"|"&$E23&"|"&$AC23 | AE23: =IF($W23<>"","⚑ "&$W23&CHAR(10),"")&TEXT($F23,"hh:mm")&"-"&TEXT($G23,"hh:mm")&IF(OR($P23="Quinzaine A",AND($P23="Hebdo · groupes alternés",$C23="A"))," Q-A",IF(OR($P23="Quinzaine B",AND($P23="Hebdo · groupes alternés",$C23="B"))," Q-B",IF($P23="Exception"," PONCT.","")))&IF($X23="Oui"," OPT","")&CHAR(10)&$K23&CHAR(10)&$M23&IF($N23<>"",CHAR(10)&"Salle "&$N23,"")&IF($O23="En ligne",CHAR(10)&"EN LIGNE","")&IF($V23<>"",CHAR(10)&$V23,"") | AF23: 19h30-21h Math (Haythem) | AG23: du 14-09 jusquà le 20-09!H52
A24: S1 | B24: du 14 au 20 septembre 2026 | C24: A | D24: 46280 | E24: Mardi | F24: 0.80208333 | G24: 0.86458333 | H24: =IF(OR($F24="",$G24=""),"",($G24-$F24)*24) | I24: Secondaire | J24: 2éme Eco | K24: Anglais | L24: Anglais | M24: Imen Bennour | P24: Quinzaine A | Q24: 2éme Eco + 2éme SCE + 2éme INFO | R24: 3 | S24: Oui | T24: S1-018 | U24: Original (septembre) | Y24: =IF($M24="","",IF(SUMPRODUCT(($D$4:$D$863=$D24)*($M$4:$M$863=$M24)*($T$4:$T$863<>$T24)*($F$4:$F$863<$G24)*($G$4:$G$863>$F24))>0,"⚠ CONFLIT","")) | Z24: =IF($J24="","",IF(SUMPRODUCT(($D$4:$D$863=$D24)*($J$4:$J$863=$J24)*($T$4:$T$863<>$T24)*($F$4:$F$863<$G24)*($G$4:$G$863>$F24)*(1-($X$4:$X$863="Oui")*($X24="Oui")))>0,"⚠ CONFLIT","")) | AA24: =IF(COUNTIFS($D$4:$D$863,$D24,$J$4:$J$863,$J24,$F$4:$F$863,$F24,$K$4:$K$863,$K24)>1,"⚠ DOUBLON","") | AB24: =IF(COUNTIF($T$4:$T$863,$T24)<>COUNTIFS($T$4:$T$863,$T24,$D$4:$D$863,$D24,$F$4:$F$863,$F24,$G$4:$G$863,$G24,$K$4:$K$863,$K24,$M$4:$M$863,$M24),"⚠ INCOHÉRENT","") | AC24: =COUNTIFS($A$4:$A24,$A24,$J$4:$J24,$J24,$E$4:$E24,$E24) | AD24: =$A24&"|"&$J24&"|"&$E24&"|"&$AC24 | AE24: =IF($W24<>"","⚑ "&$W24&CHAR(10),"")&TEXT($F24,"hh:mm")&"-"&TEXT($G24,"hh:mm")&IF(OR($P24="Quinzaine A",AND($P24="Hebdo · groupes alternés",$C24="A"))," Q-A",IF(OR($P24="Quinzaine B",AND($P24="Hebdo · groupes alternés",$C24="B"))," Q-B",IF($P24="Exception"," PONCT.","")))&IF($X24="Oui"," OPT","")&CHAR(10)&$K24&CHAR(10)&$M24&IF($N24<>"",CHAR(10)&"Salle "&$N24,"")&IF($O24="En ligne",CHAR(10)&"EN LIGNE","")&IF($V24<>"",CHAR(10)&$V24,"") | AF24: 19h15-20h45 Anglais /par quinzaine (Imen Bennour) | AG24: du 14-09 jusquà le 20-09!H56
A25: S1 | B25: du 14 au 20 septembre 2026 | C25: A | D25: 46280 | E25: Mardi | F25: 0.80208333 | G25: 0.86458333 | H25: =IF(OR($F25="",$G25=""),"",($G25-$F25)*24) | I25: Secondaire | J25: 2éme SCE | K25: Anglais | L25: Anglais | M25: Imen Bennour | P25: Quinzaine A | Q25: 2éme Eco + 2éme SCE + 2éme INFO | R25: 3 | T25: S1-018 | U25: Original (septembre) | Y25: =IF($M25="","",IF(SUMPRODUCT(($D$4:$D$863=$D25)*($M$4:$M$863=$M25)*($T$4:$T$863<>$T25)*($F$4:$F$863<$G25)*($G$4:$G$863>$F25))>0,"⚠ CONFLIT","")) | Z25: =IF($J25="","",IF(SUMPRODUCT(($D$4:$D$863=$D25)*($J$4:$J$863=$J25)*($T$4:$T$863<>$T25)*($F$4:$F$863<$G25)*($G$4:$G$863>$F25)*(1-($X$4:$X$863="Oui")*($X25="Oui")))>0,"⚠ CONFLIT","")) | AA25: =IF(COUNTIFS($D$4:$D$863,$D25,$J$4:$J$863,$J25,$F$4:$F$863,$F25,$K$4:$K$863,$K25)>1,"⚠ DOUBLON","") | AB25: =IF(COUNTIF($T$4:$T$863,$T25)<>COUNTIFS($T$4:$T$863,$T25,$D$4:$D$863,$D25,$F$4:$F$863,$F25,$G$4:$G$863,$G25,$K$4:$K$863,$K25,$M$4:$M$863,$M25),"⚠ INCOHÉRENT","") | AC25: =COUNTIFS($A$4:$A25,$A25,$J$4:$J25,$J25,$E$4:$E25,$E25) | AD25: =$A25&"|"&$J25&"|"&$E25&"|"&$AC25 | AE25: =IF($W25<>"","⚑ "&$W25&CHAR(10),"")&TEXT($F25,"hh:mm")&"-"&TEXT($G25,"hh:mm")&IF(OR($P25="Quinzaine A",AND($P25="Hebdo · groupes alternés",$C25="A"))," Q-A",IF(OR($P25="Quinzaine B",AND($P25="Hebdo · groupes alternés",$C25="B"))," Q-B",IF($P25="Exception"," PONCT.","")))&IF($X25="Oui"," OPT","")&CHAR(10)&$K25&CHAR(10)&$M25&IF($N25<>"",CHAR(10)&"Salle "&$N25,"")&IF($O25="En ligne",CHAR(10)&"EN LIGNE","")&IF($V25<>"",CHAR(10)&$V25,"") | AF25: 19h15-20h45 Anglais /par quinzaine (Imen Bennour) | AG25: du 14-09 jusquà le 20-09!H56
A26: S1 | B26: du 14 au 20 septembre 2026 | C26: A | D26: 46280 | E26: Mardi | F26: 0.80208333 | G26: 0.86458333 | H26: =IF(OR($F26="",$G26=""),"",($G26-$F26)*24) | I26: Secondaire | J26: 2éme INFO | K26: Anglais | L26: Anglais | M26: Imen Bennour | P26: Quinzaine A | Q26: 2éme Eco + 2éme SCE + 2éme INFO | R26: 3 | T26: S1-018 | U26: Original (septembre) | Y26: =IF($M26="","",IF(SUMPRODUCT(($D$4:$D$863=$D26)*($M$4:$M$863=$M26)*($T$4:$T$863<>$T26)*($F$4:$F$863<$G26)*($G$4:$G$863>$F26))>0,"⚠ CONFLIT","")) | Z26: =IF($J26="","",IF(SUMPRODUCT(($D$4:$D$863=$D26)*($J$4:$J$863=$J26)*($T$4:$T$863<>$T26)*($F$4:$F$863<$G26)*($G$4:$G$863>$F26)*(1-($X$4:$X$863="Oui")*($X26="Oui")))>0,"⚠ CONFLIT","")) | AA26: =IF(COUNTIFS($D$4:$D$863,$D26,$J$4:$J$863,$J26,$F$4:$F$863,$F26,$K$4:$K$863,$K26)>1,"⚠ DOUBLON","") | AB26: =IF(COUNTIF($T$4:$T$863,$T26)<>COUNTIFS($T$4:$T$863,$T26,$D$4:$D$863,$D26,$F$4:$F$863,$F26,$G$4:$G$863,$G26,$K$4:$K$863,$K26,$M$4:$M$863,$M26),"⚠ INCOHÉRENT","") | AC26: =COUNTIFS($A$4:$A26,$A26,$J$4:$J26,$J26,$E$4:$E26,$E26) | AD26: =$A26&"|"&$J26&"|"&$E26&"|"&$AC26 | AE26: =IF($W26<>"","⚑ "&$W26&CHAR(10),"")&TEXT($F26,"hh:mm")&"-"&TEXT($G26,"hh:mm")&IF(OR($P26="Quinzaine A",AND($P26="Hebdo · groupes alternés",$C26="A"))," Q-A",IF(OR($P26="Quinzaine B",AND($P26="Hebdo · groupes alternés",$C26="B"))," Q-B",IF($P26="Exception"," PONCT.","")))&IF($X26="Oui"," OPT","")&CHAR(10)&$K26&CHAR(10)&$M26&IF($N26<>"",CHAR(10)&"Salle "&$N26,"")&IF($O26="En ligne",CHAR(10)&"EN LIGNE","")&IF($V26<>"",CHAR(10)&$V26,"") | AF26: 19h15-20h45 Anglais /par quinzaine (Imen Bennour) | AG26: du 14-09 jusquà le 20-09!H56
A27: S1 | B27: du 14 au 20 septembre 2026 | C27: A | D27: 46280 | E27: Mardi | F27: 0.80208333 | G27: 0.86458333 | H27: =IF(OR($F27="",$G27=""),"",($G27-$F27)*24) | I27: Bac | J27: Bac Eco | K27: Espagnol | L27: Espagnol | M27: Imen | P27: Hebdo · groupes alternés | Q27: Bac Eco + Bac SCE | R27: 2 | S27: Oui | T27: S1-019 | U27: Original (septembre) | X27: Oui | Y27: =IF($M27="","",IF(SUMPRODUCT(($D$4:$D$863=$D27)*($M$4:$M$863=$M27)*($T$4:$T$863<>$T27)*($F$4:$F$863<$G27)*($G$4:$G$863>$F27))>0,"⚠ CONFLIT","")) | Z27: =IF($J27="","",IF(SUMPRODUCT(($D$4:$D$863=$D27)*($J$4:$J$863=$J27)*($T$4:$T$863<>$T27)*($F$4:$F$863<$G27)*($G$4:$G$863>$F27)*(1-($X$4:$X$863="Oui")*($X27="Oui")))>0,"⚠ CONFLIT","")) | AA27: =IF(COUNTIFS($D$4:$D$863,$D27,$J$4:$J$863,$J27,$F$4:$F$863,$F27,$K$4:$K$863,$K27)>1,"⚠ DOUBLON","") | AB27: =IF(COUNTIF($T$4:$T$863,$T27)<>COUNTIFS($T$4:$T$863,$T27,$D$4:$D$863,$D27,$F$4:$F$863,$F27,$G$4:$G$863,$G27,$K$4:$K$863,$K27,$M$4:$M$863,$M27),"⚠ INCOHÉRENT","") | AC27: =COUNTIFS($A$4:$A27,$A27,$J$4:$J27,$J27,$E$4:$E27,$E27) | AD27: =$A27&"|"&$J27&"|"&$E27&"|"&$AC27 | AE27: =IF($W27<>"","⚑ "&$W27&CHAR(10),"")&TEXT($F27,"hh:mm")&"-"&TEXT($G27,"hh:mm")&IF(OR($P27="Quinzaine A",AND($P27="Hebdo · groupes alternés",$C27="A"))," Q-A",IF(OR($P27="Quinzaine B",AND($P27="Hebdo · groupes alternés",$C27="B"))," Q-B",IF($P27="Exception"," PONCT.","")))&IF($X27="Oui"," OPT","")&CHAR(10)&$K27&CHAR(10)&$M27&IF($N27<>"",CHAR(10)&"Salle "&$N27,"")&IF($O27="En ligne",CHAR(10)&"EN LIGNE","")&IF($V27<>"",CHAR(10)&$V27,"") | AF27: 19h15-20h45 Espagnol (Imen) | AG27: du 14-09 jusquà le 20-09!H68
A28: S1 | B28: du 14 au 20 septembre 2026 | C28: A | D28: 46280 | E28: Mardi | F28: 0.80208333 | G28: 0.86458333 | H28: =IF(OR($F28="",$G28=""),"",($G28-$F28)*24) | I28: Bac | J28: Bac SCE | K28: Espagnol | L28: Espagnol | M28: Imen | P28: Hebdo · groupes alternés | Q28: Bac Eco + Bac SCE | R28: 2 | T28: S1-019 | U28: Original (septembre) | X28: Oui | Y28: =IF($M28="","",IF(SUMPRODUCT(($D$4:$D$863=$D28)*($M$4:$M$863=$M28)*($T$4:$T$863<>$T28)*($F$4:$F$863<$G28)*($G$4:$G$863>$F28))>0,"⚠ CONFLIT","")) | Z28: =IF($J28="","",IF(SUMPRODUCT(($D$4:$D$863=$D28)*($J$4:$J$863=$J28)*($T$4:$T$863<>$T28)*($F$4:$F$863<$G28)*($G$4:$G$863>$F28)*(1-($X$4:$X$863="Oui")*($X28="Oui")))>0,"⚠ CONFLIT","")) | AA28: =IF(COUNTIFS($D$4:$D$863,$D28,$J$4:$J$863,$J28,$F$4:$F$863,$F28,$K$4:$K$863,$K28)>1,"⚠ DOUBLON","") | AB28: =IF(COUNTIF($T$4:$T$863,$T28)<>COUNTIFS($T$4:$T$863,$T28,$D$4:$D$863,$D28,$F$4:$F$863,$F28,$G$4:$G$863,$G28,$K$4:$K$863,$K28,$M$4:$M$863,$M28),"⚠ INCOHÉRENT","") | AC28: =COUNTIFS($A$4:$A28,$A28,$J$4:$J28,$J28,$E$4:$E28,$E28) | AD28: =$A28&"|"&$J28&"|"&$E28&"|"&$AC28 | AE28: =IF($W28<>"","⚑ "&$W28&CHAR(10),"")&TEXT($F28,"hh:mm")&"-"&TEXT($G28,"hh:mm")&IF(OR($P28="Quinzaine A",AND($P28="Hebdo · groupes alternés",$C28="A"))," Q-A",IF(OR($P28="Quinzaine B",AND($P28="Hebdo · groupes alternés",$C28="B"))," Q-B",IF($P28="Exception"," PONCT.","")))&IF($X28="Oui"," OPT","")&CHAR(10)&$K28&CHAR(10)&$M28&IF($N28<>"",CHAR(10)&"Salle "&$N28,"")&IF($O28="En ligne",CHAR(10)&"EN LIGNE","")&IF($V28<>"",CHAR(10)&$V28,"") | AF28: 19h15-20h45 Espagnol (Imen) | AG28: du 14-09 jusquà le 20-09!H68
A29: S1 | B29: du 14 au 20 septembre 2026 | C29: A | D29: 46280 | E29: Mardi | F29: 0.80208333 | G29: 0.86458333 | H29: =IF(OR($F29="",$G29=""),"",($G29-$F29)*24) | I29: Bac | J29: Bac SCE | K29: Italien | L29: Italien | M29: Amel | P29: Hebdo · groupes alternés | Q29: Bac SCE + Bac INFO | R29: 2 | S29: Oui | T29: S1-020 | U29: Original (septembre) | X29: Oui | Y29: =IF($M29="","",IF(SUMPRODUCT(($D$4:$D$863=$D29)*($M$4:$M$863=$M29)*($T$4:$T$863<>$T29)*($F$4:$F$863<$G29)*($G$4:$G$863>$F29))>0,"⚠ CONFLIT","")) | Z29: =IF($J29="","",IF(SUMPRODUCT(($D$4:$D$863=$D29)*($J$4:$J$863=$J29)*($T$4:$T$863<>$T29)*($F$4:$F$863<$G29)*($G$4:$G$863>$F29)*(1-($X$4:$X$863="Oui")*($X29="Oui")))>0,"⚠ CONFLIT","")) | AA29: =IF(COUNTIFS($D$4:$D$863,$D29,$J$4:$J$863,$J29,$F$4:$F$863,$F29,$K$4:$K$863,$K29)>1,"⚠ DOUBLON","") | AB29: =IF(COUNTIF($T$4:$T$863,$T29)<>COUNTIFS($T$4:$T$863,$T29,$D$4:$D$863,$D29,$F$4:$F$863,$F29,$G$4:$G$863,$G29,$K$4:$K$863,$K29,$M$4:$M$863,$M29),"⚠ INCOHÉRENT","") | AC29: =COUNTIFS($A$4:$A29,$A29,$J$4:$J29,$J29,$E$4:$E29,$E29) | AD29: =$A29&"|"&$J29&"|"&$E29&"|"&$AC29 | AE29: =IF($W29<>"","⚑ "&$W29&CHAR(10),"")&TEXT($F29,"hh:mm")&"-"&TEXT($G29,"hh:mm")&IF(OR($P29="Quinzaine A",AND($P29="Hebdo · groupes alternés",$C29="A"))," Q-A",IF(OR($P29="Quinzaine B",AND($P29="Hebdo · groupes alternés",$C29="B"))," Q-B",IF($P29="Exception"," PONCT.","")))&IF($X29="Oui"," OPT","")&CHAR(10)&$K29&CHAR(10)&$M29&IF($N29<>"",CHAR(10)&"Salle "&$N29,"")&IF($O29="En ligne",CHAR(10)&"EN LIGNE","")&IF($V29<>"",CHAR(10)&$V29,"") | AF29: 19h15-20h45 Italien (Amel) | AG29: du 14-09 jusquà le 20-09!H76
A30: S1 | B30: du 14 au 20 septembre 2026 | C30: A | D30: 46280 | E30: Mardi | F30: 0.80208333 | G30: 0.86458333 | H30: =IF(OR($F30="",$G30=""),"",($G30-$F30)*24) | I30: Bac | J30: Bac INFO | K30: Italien | L30: Italien | M30: Amel | P30: Hebdo · groupes alternés | Q30: Bac SCE + Bac INFO | R30: 2 | T30: S1-020 | U30: Original (septembre) | X30: Oui | Y30: =IF($M30="","",IF(SUMPRODUCT(($D$4:$D$863=$D30)*($M$4:$M$863=$M30)*($T$4:$T$863<>$T30)*($F$4:$F$863<$G30)*($G$4:$G$863>$F30))>0,"⚠ CONFLIT","")) | Z30: =IF($J30="","",IF(SUMPRODUCT(($D$4:$D$863=$D30)*($J$4:$J$863=$J30)*($T$4:$T$863<>$T30)*($F$4:$F$863<$G30)*($G$4:$G$863>$F30)*(1-($X$4:$X$863="Oui")*($X30="Oui")))>0,"⚠ CONFLIT","")) | AA30: =IF(COUNTIFS($D$4:$D$863,$D30,$J$4:$J$863,$J30,$F$4:$F$863,$F30,$K$4:$K$863,$K30)>1,"⚠ DOUBLON","") | AB30: =IF(COUNTIF($T$4:$T$863,$T30)<>COUNTIFS($T$4:$T$863,$T30,$D$4:$D$863,$D30,$F$4:$F$863,$F30,$G$4:$G$863,$G30,$K$4:$K$863,$K30,$M$4:$M$863,$M30),"⚠ INCOHÉRENT","") | AC30: =COUNTIFS($A$4:$A30,$A30,$J$4:$J30,$J30,$E$4:$E30,$E30) | AD30: =$A30&"|"&$J30&"|"&$E30&"|"&$AC30 | AE30: =IF($W30<>"","⚑ "&$W30&CHAR(10),"")&TEXT($F30,"hh:mm")&"-"&TEXT($G30,"hh:mm")&IF(OR($P30="Quinzaine A",AND($P30="Hebdo · groupes alternés",$C30="A"))," Q-A",IF(OR($P30="Quinzaine B",AND($P30="Hebdo · groupes alternés",$C30="B"))," Q-B",IF($P30="Exception"," PONCT.","")))&IF($X30="Oui"," OPT","")&CHAR(10)&$K30&CHAR(10)&$M30&IF($N30<>"",CHAR(10)&"Salle "&$N30,"")&IF($O30="En ligne",CHAR(10)&"EN LIGNE","")&IF($V30<>"",CHAR(10)&$V30,"") | AF30: 19h15-20h45 Italien (Amel) | AG30: du 14-09 jusquà le 20-09!H76
A31: S1 | B31: du 14 au 20 septembre 2026 | C31: A | D31: 46281 | E31: Mercredi | F31: 0.79166667 | G31: 0.875 | H31: =IF(OR($F31="",$G31=""),"",($G31-$F31)*24) | I31: Primaire | J31: 4éme | K31: رياضيات | L31: Math | M31: Bassma | P31: Hebdomadaire | R31: 1 | S31: Oui | T31: S1-021 | U31: Original (septembre) | Y31: =IF($M31="","",IF(SUMPRODUCT(($D$4:$D$863=$D31)*($M$4:$M$863=$M31)*($T$4:$T$863<>$T31)*($F$4:$F$863<$G31)*($G$4:$G$863>$F31))>0,"⚠ CONFLIT","")) | Z31: =IF($J31="","",IF(SUMPRODUCT(($D$4:$D$863=$D31)*($J$4:$J$863=$J31)*($T$4:$T$863<>$T31)*($F$4:$F$863<$G31)*($G$4:$G$863>$F31)*(1-($X$4:$X$863="Oui")*($X31="Oui")))>0,"⚠ CONFLIT","")) | AA31: =IF(COUNTIFS($D$4:$D$863,$D31,$J$4:$J$863,$J31,$F$4:$F$863,$F31,$K$4:$K$863,$K31)>1,"⚠ DOUBLON","") | AB31: =IF(COUNTIF($T$4:$T$863,$T31)<>COUNTIFS($T$4:$T$863,$T31,$D$4:$D$863,$D31,$F$4:$F$863,$F31,$G$4:$G$863,$G31,$K$4:$K$863,$K31,$M$4:$M$863,$M31),"⚠ INCOHÉRENT","") | AC31: =COUNTIFS($A$4:$A31,$A31,$J$4:$J31,$J31,$E$4:$E31,$E31) | AD31: =$A31&"|"&$J31&"|"&$E31&"|"&$AC31 | AE31: =IF($W31<>"","⚑ "&$W31&CHAR(10),"")&TEXT($F31,"hh:mm")&"-"&TEXT($G31,"hh:mm")&IF(OR($P31="Quinzaine A",AND($P31="Hebdo · groupes alternés",$C31="A"))," Q-A",IF(OR($P31="Quinzaine B",AND($P31="Hebdo · groupes alternés",$C31="B"))," Q-B",IF($P31="Exception"," PONCT.","")))&IF($X31="Oui"," OPT","")&CHAR(10)&$K31&CHAR(10)&$M31&IF($N31<>"",CHAR(10)&"Salle "&$N31,"")&IF($O31="En ligne",CHAR(10)&"EN LIGNE","")&IF($V31<>"",CHAR(10)&$V31,"") | AF31: 19h-21h رياضيات (Bassma) | AG31: du 14-09 jusquà le 20-09!I3
A32: S1 | B32: du 14 au 20 septembre 2026 | C32: A | D32: 46281 | E32: Mercredi | F32: 0.79166667 | G32: 0.875 | H32: =IF(OR($F32="",$G32=""),"",($G32-$F32)*24) | I32: Primaire | J32: 6éme Pilote (A) | K32: رياضيات | L32: Math | M32: Noura | P32: Hebdomadaire | R32: 1 | S32: Oui | T32: S1-022 | U32: Original (septembre) | Y32: =IF($M32="","",IF(SUMPRODUCT(($D$4:$D$863=$D32)*($M$4:$M$863=$M32)*($T$4:$T$863<>$T32)*($F$4:$F$863<$G32)*($G$4:$G$863>$F32))>0,"⚠ CONFLIT","")) | Z32: =IF($J32="","",IF(SUMPRODUCT(($D$4:$D$863=$D32)*($J$4:$J$863=$J32)*($T$4:$T$863<>$T32)*($F$4:$F$863<$G32)*($G$4:$G$863>$F32)*(1-($X$4:$X$863="Oui")*($X32="Oui")))>0,"⚠ CONFLIT","")) | AA32: =IF(COUNTIFS($D$4:$D$863,$D32,$J$4:$J$863,$J32,$F$4:$F$863,$F32,$K$4:$K$863,$K32)>1,"⚠ DOUBLON","") | AB32: =IF(COUNTIF($T$4:$T$863,$T32)<>COUNTIFS($T$4:$T$863,$T32,$D$4:$D$863,$D32,$F$4:$F$863,$F32,$G$4:$G$863,$G32,$K$4:$K$863,$K32,$M$4:$M$863,$M32),"⚠ INCOHÉRENT","") | AC32: =COUNTIFS($A$4:$A32,$A32,$J$4:$J32,$J32,$E$4:$E32,$E32) | AD32: =$A32&"|"&$J32&"|"&$E32&"|"&$AC32 | AE32: =IF($W32<>"","⚑ "&$W32&CHAR(10),"")&TEXT($F32,"hh:mm")&"-"&TEXT($G32,"hh:mm")&IF(OR($P32="Quinzaine A",AND($P32="Hebdo · groupes alternés",$C32="A"))," Q-A",IF(OR($P32="Quinzaine B",AND($P32="Hebdo · groupes alternés",$C32="B"))," Q-B",IF($P32="Exception"," PONCT.","")))&IF($X32="Oui"," OPT","")&CHAR(10)&$K32&CHAR(10)&$M32&IF($N32<>"",CHAR(10)&"Salle "&$N32,"")&IF($O32="En ligne",CHAR(10)&"EN LIGNE","")&IF($V32<>"",CHAR(10)&$V32,"") | AF32: 19h-21h رياضيات (Noura) | AG32: du 14-09 jusquà le 20-09!I12
A33: S1 | B33: du 14 au 20 septembre 2026 | C33: A | D33: 46281 | E33: Mercredi | F33: 0.8125 | G33: 0.875 | H33: =IF(OR($F33="",$G33=""),"",($G33-$F33)*24) | I33: Collège | J33: 7éme (A) | K33: فيزياء | L33: Physique | M33: Melek | P33: Hebdomadaire | Q33: 7éme (A) + 7éme (B) | R33: 2 | S33: Oui | T33: S1-023 | U33: Original (septembre) | Y33: =IF($M33="","",IF(SUMPRODUCT(($D$4:$D$863=$D33)*($M$4:$M$863=$M33)*($T$4:$T$863<>$T33)*($F$4:$F$863<$G33)*($G$4:$G$863>$F33))>0,"⚠ CONFLIT","")) | Z33: =IF($J33="","",IF(SUMPRODUCT(($D$4:$D$863=$D33)*($J$4:$J$863=$J33)*($T$4:$T$863<>$T33)*($F$4:$F$863<$G33)*($G$4:$G$863>$F33)*(1-($X$4:$X$863="Oui")*($X33="Oui")))>0,"⚠ CONFLIT","")) | AA33: =IF(COUNTIFS($D$4:$D$863,$D33,$J$4:$J$863,$J33,$F$4:$F$863,$F33,$K$4:$K$863,$K33)>1,"⚠ DOUBLON","") | AB33: =IF(COUNTIF($T$4:$T$863,$T33)<>COUNTIFS($T$4:$T$863,$T33,$D$4:$D$863,$D33,$F$4:$F$863,$F33,$G$4:$G$863,$G33,$K$4:$K$863,$K33,$M$4:$M$863,$M33),"⚠ INCOHÉRENT","") | AC33: =COUNTIFS($A$4:$A33,$A33,$J$4:$J33,$J33,$E$4:$E33,$E33) | AD33: =$A33&"|"&$J33&"|"&$E33&"|"&$AC33 | AE33: =IF($W33<>"","⚑ "&$W33&CHAR(10),"")&TEXT($F33,"hh:mm")&"-"&TEXT($G33,"hh:mm")&IF(OR($P33="Quinzaine A",AND($P33="Hebdo · groupes alternés",$C33="A"))," Q-A",IF(OR($P33="Quinzaine B",AND($P33="Hebdo · groupes alternés",$C33="B"))," Q-B",IF($P33="Exception"," PONCT.","")))&IF($X33="Oui"," OPT","")&CHAR(10)&$K33&CHAR(10)&$M33&IF($N33<>"",CHAR(10)&"Salle "&$N33,"")&IF($O33="En ligne",CHAR(10)&"EN LIGNE","")&IF($V33<>"",CHAR(10)&$V33,"") | AF33: 19h30-21h فيزياء /par quinzaine (Melek) | AG33: du 14-09 jusquà le 20-09!I19
A34: S1 | B34: du 14 au 20 septembre 2026 | C34: A | D34: 46281 | E34: Mercredi | F34: 0.8125 | G34: 0.875 | H34: =IF(OR($F34="",$G34=""),"",($G34-$F34)*24) | I34: Collège | J34: 7éme (B) | K34: فيزياء | L34: Physique | M34: Melek | P34: Hebdomadaire | Q34: 7éme (A) + 7éme (B) | R34: 2 | T34: S1-023 | U34: Original (septembre) | Y34: =IF($M34="","",IF(SUMPRODUCT(($D$4:$D$863=$D34)*($M$4:$M$863=$M34)*($T$4:$T$863<>$T34)*($F$4:$F$863<$G34)*($G$4:$G$863>$F34))>0,"⚠ CONFLIT","")) | Z34: =IF($J34="","",IF(SUMPRODUCT(($D$4:$D$863=$D34)*($J$4:$J$863=$J34)*($T$4:$T$863<>$T34)*($F$4:$F$863<$G34)*($G$4:$G$863>$F34)*(1-($X$4:$X$863="Oui")*($X34="Oui")))>0,"⚠ CONFLIT","")) | AA34: =IF(COUNTIFS($D$4:$D$863,$D34,$J$4:$J$863,$J34,$F$4:$F$863,$F34,$K$4:$K$863,$K34)>1,"⚠ DOUBLON","") | AB34: =IF(COUNTIF($T$4:$T$863,$T34)<>COUNTIFS($T$4:$T$863,$T34,$D$4:$D$863,$D34,$F$4:$F$863,$F34,$G$4:$G$863,$G34,$K$4:$K$863,$K34,$M$4:$M$863,$M34),"⚠ INCOHÉRENT","") | AC34: =COUNTIFS($A$4:$A34,$A34,$J$4:$J34,$J34,$E$4:$E34,$E34) | AD34: =$A34&"|"&$J34&"|"&$E34&"|"&$AC34 | AE34: =IF($W34<>"","⚑ "&$W34&CHAR(10),"")&TEXT($F34,"hh:mm")&"-"&TEXT($G34,"hh:mm")&IF(OR($P34="Quinzaine A",AND($P34="Hebdo · groupes alternés",$C34="A"))," Q-A",IF(OR($P34="Quinzaine B",AND($P34="Hebdo · groupes alternés",$C34="B"))," Q-B",IF($P34="Exception"," PONCT.","")))&IF($X34="Oui"," OPT","")&CHAR(10)&$K34&CHAR(10)&$M34&IF($N34<>"",CHAR(10)&"Salle "&$N34,"")&IF($O34="En ligne",CHAR(10)&"EN LIGNE","")&IF($V34<>"",CHAR(10)&$V34,"") | AF34: 19h30-21h فيزياء /par quinzaine (Melek) | AG34: du 14-09 jusquà le 20-09!I19
A35: S1 | B35: du 14 au 20 septembre 2026 | C35: A | D35: 46281 | E35: Mercredi | F35: 0.79166667 | G35: 0.85416667 | H35: =IF(OR($F35="",$G35=""),"",($G35-$F35)*24) | I35: Collège | J35: 8éme (A) | K35: Arabe | L35: Arabe | M35: Awatef | P35: Hebdomadaire | R35: 1 | S35: Oui | T35: S1-024 | U35: Original (septembre) | Y35: =IF($M35="","",IF(SUMPRODUCT(($D$4:$D$863=$D35)*($M$4:$M$863=$M35)*($T$4:$T$863<>$T35)*($F$4:$F$863<$G35)*($G$4:$G$863>$F35))>0,"⚠ CONFLIT","")) | Z35: =IF($J35="","",IF(SUMPRODUCT(($D$4:$D$863=$D35)*($J$4:$J$863=$J35)*($T$4:$T$863<>$T35)*($F$4:$F$863<$G35)*($G$4:$G$863>$F35)*(1-($X$4:$X$863="Oui")*($X35="Oui")))>0,"⚠ CONFLIT","")) | AA35: =IF(COUNTIFS($D$4:$D$863,$D35,$J$4:$J$863,$J35,$F$4:$F$863,$F35,$K$4:$K$863,$K35)>1,"⚠ DOUBLON","") | AB35: =IF(COUNTIF($T$4:$T$863,$T35)<>COUNTIFS($T$4:$T$863,$T35,$D$4:$D$863,$D35,$F$4:$F$863,$F35,$G$4:$G$863,$G35,$K$4:$K$863,$K35,$M$4:$M$863,$M35),"⚠ INCOHÉRENT","") | AC35: =COUNTIFS($A$4:$A35,$A35,$J$4:$J35,$J35,$E$4:$E35,$E35) | AD35: =$A35&"|"&$J35&"|"&$E35&"|"&$AC35 | AE35: =IF($W35<>"","⚑ "&$W35&CHAR(10),"")&TEXT($F35,"hh:mm")&"-"&TEXT($G35,"hh:mm")&IF(OR($P35="Quinzaine A",AND($P35="Hebdo · groupes alternés",$C35="A"))," Q-A",IF(OR($P35="Quinzaine B",AND($P35="Hebdo · groupes alternés",$C35="B"))," Q-B",IF($P35="Exception"," PONCT.","")))&IF($X35="Oui"," OPT","")&CHAR(10)&$K35&CHAR(10)&$M35&IF($N35<>"",CHAR(10)&"Salle "&$N35,"")&IF($O35="En ligne",CHAR(10)&"EN LIGNE","")&IF($V35<>"",CHAR(10)&$V35,"") | AF35: 19h-20h30 Arabe (Awatef) | AG35: du 14-09 jusquà le 20-09!I27
A36: S1 | B36: du 14 au 20 septembre 2026 | C36: A | D36: 46281 | E36: Mercredi | F36: 0.80208333 | G36: 0.86458333 | H36: =IF(OR($F36="",$G36=""),"",($G36-$F36)*24) | I36: Collège | J36: 8éme (B) | K36: Math | L36: Math | M36: Khouloud | P36: Hebdomadaire | R36: 1 | S36: Oui | T36: S1-025 | U36: Original (septembre) | Y36: =IF($M36="","",IF(SUMPRODUCT(($D$4:$D$863=$D36)*($M$4:$M$863=$M36)*($T$4:$T$863<>$T36)*($F$4:$F$863<$G36)*($G$4:$G$863>$F36))>0,"⚠ CONFLIT","")) | Z36: =IF($J36="","",IF(SUMPRODUCT(($D$4:$D$863=$D36)*($J$4:$J$863=$J36)*($T$4:$T$863<>$T36)*($F$4:$F$863<$G36)*($G$4:$G$863>$F36)*(1-($X$4:$X$863="Oui")*($X36="Oui")))>0,"⚠ CONFLIT","")) | AA36: =IF(COUNTIFS($D$4:$D$863,$D36,$J$4:$J$863,$J36,$F$4:$F$863,$F36,$K$4:$K$863,$K36)>1,"⚠ DOUBLON","") | AB36: =IF(COUNTIF($T$4:$T$863,$T36)<>COUNTIFS($T$4:$T$863,$T36,$D$4:$D$863,$D36,$F$4:$F$863,$F36,$G$4:$G$863,$G36,$K$4:$K$863,$K36,$M$4:$M$863,$M36),"⚠ INCOHÉRENT","") | AC36: =COUNTIFS($A$4:$A36,$A36,$J$4:$J36,$J36,$E$4:$E36,$E36) | AD36: =$A36&"|"&$J36&"|"&$E36&"|"&$AC36 | AE36: =IF($W36<>"","⚑ "&$W36&CHAR(10),"")&TEXT($F36,"hh:mm")&"-"&TEXT($G36,"hh:mm")&IF(OR($P36="Quinzaine A",AND($P36="Hebdo · groupes alternés",$C36="A"))," Q-A",IF(OR($P36="Quinzaine B",AND($P36="Hebdo · groupes alternés",$C36="B"))," Q-B",IF($P36="Exception"," PONCT.","")))&IF($X36="Oui"," OPT","")&CHAR(10)&$K36&CHAR(10)&$M36&IF($N36<>"",CHAR(10)&"Salle "&$N36,"")&IF($O36="En ligne",CHAR(10)&"EN LIGNE","")&IF($V36<>"",CHAR(10)&$V36,"") | AF36: 19h15-20h45 Math (Khouloud) | AG36: du 14-09 jusquà le 20-09!I31
A37: S1 | B37: du 14 au 20 septembre 2026 | C37: A | D37: 46281 | E37: Mercredi | F37: 0.8125 | G37: 0.875 | H37: =IF(OR($F37="",$G37=""),"",($G37-$F37)*24) | I37: Collège | J37: 8éme (C) | K37: Français | L37: Français | M37: Nabil | P37: Hebdomadaire | R37: 1 | S37: Oui | T37: S1-026 | U37: Original (septembre) | Y37: =IF($M37="","",IF(SUMPRODUCT(($D$4:$D$863=$D37)*($M$4:$M$863=$M37)*($T$4:$T$863<>$T37)*($F$4:$F$863<$G37)*($G$4:$G$863>$F37))>0,"⚠ CONFLIT","")) | Z37: =IF($J37="","",IF(SUMPRODUCT(($D$4:$D$863=$D37)*($J$4:$J$863=$J37)*($T$4:$T$863<>$T37)*($F$4:$F$863<$G37)*($G$4:$G$863>$F37)*(1-($X$4:$X$863="Oui")*($X37="Oui")))>0,"⚠ CONFLIT","")) | AA37: =IF(COUNTIFS($D$4:$D$863,$D37,$J$4:$J$863,$J37,$F$4:$F$863,$F37,$K$4:$K$863,$K37)>1,"⚠ DOUBLON","") | AB37: =IF(COUNTIF($T$4:$T$863,$T37)<>COUNTIFS($T$4:$T$863,$T37,$D$4:$D$863,$D37,$F$4:$F$863,$F37,$G$4:$G$863,$G37,$K$4:$K$863,$K37,$M$4:$M$863,$M37),"⚠ INCOHÉRENT","") | AC37: =COUNTIFS($A$4:$A37,$A37,$J$4:$J37,$J37,$E$4:$E37,$E37) | AD37: =$A37&"|"&$J37&"|"&$E37&"|"&$AC37 | AE37: =IF($W37<>"","⚑ "&$W37&CHAR(10),"")&TEXT($F37,"hh:mm")&"-"&TEXT($G37,"hh:mm")&IF(OR($P37="Quinzaine A",AND($P37="Hebdo · groupes alternés",$C37="A"))," Q-A",IF(OR($P37="Quinzaine B",AND($P37="Hebdo · groupes alternés",$C37="B"))," Q-B",IF($P37="Exception"," PONCT.","")))&IF($X37="Oui"," OPT","")&CHAR(10)&$K37&CHAR(10)&$M37&IF($N37<>"",CHAR(10)&"Salle "&$N37,"")&IF($O37="En ligne",CHAR(10)&"EN LIGNE","")&IF($V37<>"",CHAR(10)&$V37,"") | AF37: 19h30-21h Français (Nabil) | AG37: du 14-09 jusquà le 20-09!I34
A38: S1 | B38: du 14 au 20 septembre 2026 | C38: A | D38: 46281 | E38: Mercredi | F38: 0.8125 | G38: 0.875 | H38: =IF(OR($F38="",$G38=""),"",($G38-$F38)*24) | I38: Collège | J38: 9éme (B) | K38: Arabe | L38: Arabe | M38: Yahya | P38: Hebdomadaire | R38: 1 | S38: Oui | T38: S1-027 | U38: Original (septembre) | Y38: =IF($M38="","",IF(SUMPRODUCT(($D$4:$D$863=$D38)*($M$4:$M$863=$M38)*($T$4:$T$863<>$T38)*($F$4:$F$863<$G38)*($G$4:$G$863>$F38))>0,"⚠ CONFLIT","")) | Z38: =IF($J38="","",IF(SUMPRODUCT(($D$4:$D$863=$D38)*($J$4:$J$863=$J38)*($T$4:$T$863<>$T38)*($F$4:$F$863<$G38)*($G$4:$G$863>$F38)*(1-($X$4:$X$863="Oui")*($X38="Oui")))>0,"⚠ CONFLIT","")) | AA38: =IF(COUNTIFS($D$4:$D$863,$D38,$J$4:$J$863,$J38,$F$4:$F$863,$F38,$K$4:$K$863,$K38)>1,"⚠ DOUBLON","") | AB38: =IF(COUNTIF($T$4:$T$863,$T38)<>COUNTIFS($T$4:$T$863,$T38,$D$4:$D$863,$D38,$F$4:$F$863,$F38,$G$4:$G$863,$G38,$K$4:$K$863,$K38,$M$4:$M$863,$M38),"⚠ INCOHÉRENT","") | AC38: =COUNTIFS($A$4:$A38,$A38,$J$4:$J38,$J38,$E$4:$E38,$E38) | AD38: =$A38&"|"&$J38&"|"&$E38&"|"&$AC38 | AE38: =IF($W38<>"","⚑ "&$W38&CHAR(10),"")&TEXT($F38,"hh:mm")&"-"&TEXT($G38,"hh:mm")&IF(OR($P38="Quinzaine A",AND($P38="Hebdo · groupes alternés",$C38="A"))," Q-A",IF(OR($P38="Quinzaine B",AND($P38="Hebdo · groupes alternés",$C38="B"))," Q-B",IF($P38="Exception"," PONCT.","")))&IF($X38="Oui"," OPT","")&CHAR(10)&$K38&CHAR(10)&$M38&IF($N38<>"",CHAR(10)&"Salle "&$N38,"")&IF($O38="En ligne",CHAR(10)&"EN LIGNE","")&IF($V38<>"",CHAR(10)&$V38,"") | AF38: 19h30-21h Arabe (Yahya) | AG38: du 14-09 jusquà le 20-09!I43
